Workbook

Sheet A.OKR&KPI 10-12.2024
C1: A. BUSINESS OBJECTIVE | E1: Business Dashboard
C2: A1. CHỈ TIÊU KINH DOANH | G2: A2. CHỈ TIÊU KINH DOANH
C3: THÁNG 10 | D3: THÁNG 11 (*) | E3: Tháng 12 (*) | F3: TỔNG | G3: STORE | H3: THÁNG 10 | I3: Tháng 11 | J3: THÁNG 12
C4: KPI (**) | G4: 01 Tân Bình | H4: =C5*18% | I4: =D5*16.5% | J4: 1238000000
C5: 6643000000 | D5: 7500000000 | E5: 7500000000 | F5: =SUM(C5:E5) | G5: 02 Chi nhánh Q11 | H5: =C5*18% | I5: =D5*16.5% | J5: 1238000000
B6: KH CŨ | C6: =C5*50% | D6: =D5*50% | E6: =E5*50% | F6: =F5*50% | G6: 03 Thủ Đức | H6: =C5*18% | I6: =D5*16.5% | J6: 1238000000
B7: KH MỚI | C7: =C5*50% | D7: =D5*50% | E7: =E5*50% | F7: =F5*50% | G7: 04 Bình Thạnh | H7: =C5*11% | I7: 800000000 | J7: 800000000
E8: 90% KPI Set/Quý | F8: =F5*90% | G8: 05 Quận 1 | H8: =C5*9% | I8: 638500000 | J8: 638500000
B9: 90% KPI/THÁNG | C9: =C5*90% | D9: =D5*90% | E9: =E5*90% | G9: 06 Gò Vấp | H9: =C5*10% | I9: 709000000 | J9: 709000000
G10: 07 Quận 7 | H10: =C5*10% | I10: 740000000 | J10: 740000000
G11: 08 Quận 12 | H11: =C5*6% | I11: 400000000 | J11: 400000000
G12: 09 Quận 9 | I12: 500000000 | J12: 500000000 | K12: =SUM(I12:J12)
C13: (*) Doanh thu từ khai trương chi nhánh 09 Quận 9 (**) Chi phí Marketing & Đánh giá hiệu suất, cơ chế thưởng. | G13: Tổng | H13: =SUM(H4:H11) | I13: =SUM(I4:I12) | J13: =SUM(J4:J12) | K13: =SUM(H13:J13)
C14: A3. CHỈ TIÊU CUSTOMER SERVICE TEAM
C15: THÁNG 10 | D15: THÁNG 11 (*) | E15: Tháng 12 (*) | F15: TỔNG | G15: CS OKR & KPI PLAN: OKR & KPI Phòng CS
C16: KPI (*)
B17: =C17/5 | C17: =C5*23% | D17: =D5*23% | E17: =E5*23% | F17: =SUM(C17:E17)
C19: A3. PHÂN BỔ CHỈ TIÊU DOANH THU & CHI PHÍ THEO CAMPAIGN/GIAI ĐOẠN
C20: THÁNG 10.2024 | D20: THÁNG 11.2024 | E20: THÁNG 12.2024 | F20: OPENNING QUẬN 9
B21: TIME | C21: 1.10-31.10 | D21: 1.11-30.11 | E21: 1.12-31.12 | F21: 2.11-31.12
B22: DT | C22: =C5 | D22: =D5-I12 | E22: =E5-J12 | F22: =K12 | G22: =SUM(C22:F22)
B23: BUDGET (*) | C23: =C22*5% | D23: =D22*10% | E23: =E22*10% | F23: =F22*25% | G23: =SUM(C23:F23) | H23: =G23/G22
B24: Brand & Com | C24: =C23*25% | D24: =D23*40% | E24: =E23*30% | F24: =F23*60% | G24: =SUM(C24:F24) | H24: =G24/G23
B25: Paid Media | C25: =C23-C24 | D25: =D23-D24 | E25: =E23-E24 | F25: =F23-F24 | G25: =SUM(C25:F25) | H25: =G25/G23
C26: Lưu ý: 1. Có thể linh hoạt chuyển đổi chi phí giữa các giai đoạn theo tình hình thực tế nhưng phải đảm bảo ngân sách tổng. 2. Chi phí cho khai trương Quận 9 là 20%/Doanh thu dự kiến 3. Chi phí=5.7%/Doanh thu/Campaign vượt mức 5% cố định do đầu tư vào giai đoạn Tái định vị & khai trương. Trong đó cơ cấu chi phí cho hoạt động Brand & Com, Paid Ads sẽ được cân đối để đảm bảo Doanh thu & các hoạt động.
C28: B. MARKETING OBJECTIVE | I28: C. MARKETING KPI (90%)
D29: MÔ TẢ MỤC TIÊU | F29: THÁNG 10 | G29: THÁNG 11 | H29: THÁNG 12 | I29: THÁNG 10 | J29: THÁNG 11 | K29: THÁNG 12
C30: Nội dung Tái định vị | D30: Triển khai Tái định vị Phase 1: "Slogan & Câu chuyện thương hiệu"" | F30: Công bố & truyền thông Slogan "GIÁ TRỊ & TRẢI NGHIỆM" | G30: Công bố Website mới, truyền thông câu chuyện Thương hiệu & khai trương chi nhánh 09 | H30: Tiếp tục truyền thông Câu chuyện thương hiệu & triển khai 5S Tâm Đức. Duy trì khai trương Q.9 | I30: Công bố & truyền thông Slogan "GIÁ TRỊ & TRẢI NGHIỆM" | J30: Công bố Website mới, truyền thông câu chuyện Thương hiệu & khai trương chi nhánh 09 | K30: Tiếp tục truyền thông Câu chuyện thương hiệu & triển khai 5S Tâm Đức. Duy trì khai trương Q9
C31: Khách hàng | D31: Tăng trưởng mạnh mẽ nhóm khách hàng mới & tỷ lệ quay lại khách hàng cũ | F31: Khách cũ quay lại 58% | G31: Khách cũ quay lại 62% | H31: Khách cũ quay lại 62% | I31: Khách cũ 56.84% | J31: Khách cũ 60.76% | K31: Khách cũ 60.76%
F32: Khách mới Growth 10% | G32: Khách mới Growth 15% | H32: Khách mới Growth 15% | I32: Khách mới Growth 9% | J32: Khách mới Growth 13.5% | K32: Khách mới Growth 13.5%
C33: Tăng trưởng các chỉ số Owned Media | D33: Tăng trưởng qua lượng Reach trên Social Media. | F33: 2 | G33: 3 | H33: 3 | I33: 1.8 | J33: 2.7 | K33: 2.7
D34: Tăng trưởng qua lượng Engagement trên Social Media. | F34: 1.5 | G34: 2 | H34: 2 | I34: 1.35 | J34: 1.8 | K34: 1.8
D35: Tăng trưởng Traffic trên Website | F35: 0.2 | G35: 0.2 | H35: 0.2 | I35: 0.18 | J35: 0.18 | K35: 0.18
D36: Tăng trưởng Views Organic (TikTok/Facebook/Youtube) | F36: 500000 | G36: 2000000 | H36: 1000000 | I36: =F36*90% | J36: =G36*90% | K36: =H36*90%
D37: Phát triển Kênh mới | F37: Linkedin | G37: Linkedin Youtube | H37: Linkedin Youtube | I37: Linkedin | J37: Linkedin Youtube | K37: Linkedin Youtube
C38: Tạo thảo luận về Thương hiệu trên Social Media | D38: Thông qua UGC content bằng hình thức # | F38: #100 | G38: #250 | H38: #200 | I38: #90 | J38: #225 | K38: #180
C39: Tăng trưởng nhận diện Thương hiệu | D39: Qua Branded Merchandise | F39: #Sổ #giá đỡ điện thoại | G39: #Túi Tote #Nón bảo hiểm #Sổ #Giây đeo kính | H39: #Túi Tote #Nón bảo hiểm #Sổ #Giây đeo kính | I39: #Sổ #giá đỡ điện thoại | J39: #Túi Tote #Nón bảo hiểm #Sổ #Giây đeo kính | K39: #Túi Tote #Nón bảo hiểm #Sổ #Giây đeo kính
D40: Media Booking - OOH | F40: Coffee Shop, Uni OOH | I40: Coffee Shop, Uni OOH
D41: Đại sứ Thương hiệu/Đại sứ truyền thông | F41: Ông chú Polo + 1 Influencer phù hợp
D42: Activations | F42: 1. Masscot 2. Game Online | G42: 1. Masscot 2. Game Online/Offline | H42: 1.Masscot 2.Game Online/Offline | I42: 1. Masscot 2. Game Online | J42: 1. Masscot 2. Game Online/Offline | K42: 1.Masscot 2.Game Online/Offline
...

Sheet B.Marketing Plan 1.10-25.10
B2: BUSINESS KPI (1.10-25.10)
B3: DOANH THU | C3: BUDGET
A4: 25 DAY | B4: =(('A.OKR&KPI 10-12.2024'!C5/31)*25) | C4: =B4*5%
A5: DAY | B5: =B4/20 | C5: =C4/15
B6: BUDGET ALOCATION
B7: PAID ADS | C7: =C4*90%
B8: Facebook Ads | C8: =C7*90% | E8: =C8/20 | F8: DAY
B9: TikTok Ads | C9: =C7*3% | E9: =C9/20 | F9: DAY
B10: YouTuBe Ads | C10: =C7*2% | E10: =C10/20 | F10: DAY
B11: BRAND & COM | C11: =C4-C7
B12: TikTok | C12: =C11*40%
B13: Uni Tour (Activation) | C13: =C11*30%
B14: PR-Báo | C14: =C11*30%
B15: Voucher Ecolite: Tài trợ Uni Tour & Co-Branding | C15: 8.000 cái | E15: Kèm điều kiện khi phát sinh hóa đơn
B17: MARKETING OKR | E17: KPI | F17: NỘI DUNG/ACTION TRIỂN KHAI
B18: Tuyến Nội dung Tái định vị | C18: Triển khai Tái định vị Phase 1: "Slogan & Câu chuyện thương hiệu"" | E18: Công bố Câu chuyện thương hiệu trên Owned Media
B19: Tăng trưởng các chỉ số Owned Media | C19: Tăng trưởng qua lượng Reach trên Social Media. | E19: 1.8 | F19: Thay đổi cách viết storytelling. Các nhóm bài viết giới thiệu về thương hiệu dựa trên câu chuyện thương hiệu: Tầm nhìn, giá trị cốt lõi, dịch vụ,...
C20: Tăng trưởng qua lượng Engagement trên Social Media. | E20: =('A.OKR&KPI 10-12.2024'!I34/31)*20
C21: Tăng trưởng Traffic trên Website | E21: =('A.OKR&KPI 10-12.2024'!I35/31)*20 | F21: Cấu trúc nội dung Website mới với cách viết tập trung vào khách hàng & tăng chuyển đổi
C22: Tăng trưởng Views Organic | E22: =('A.OKR&KPI 10-12.2024'!I36/31)*20 | F22: Sản xuất các Video với nội dung có giá trị & focus vào khách hàng. Các nội dung bắt trend bổ trợ.
C23: Phát triển Kênh mới | E23: Linkedin | F23: Tập trung vào các tuyến nội dung về thương hiệu.
B24: Tạo thảo luận về Thương hiệu trên Social Media | C24: Thông qua UGC content bằng hình thức # | E24: #50 | F24: TikTok clip có #kinhmoibatchatmoi #matkinhtamduc
B25: PR & COM | C25: Co-Branding & Partnership | E25: BTaskee CGV | F25: Đối tác Trao đổi quyền lợi truyền thông & Tâm Đức trao đổi bằng Scheme CT khuyến mãi cho khách hàng của đối tác.
C26: Sponsor | E26: 1 | F26: Phát voucher tròng Ecolite/Voucher khác cho hoạt động này.
C27: Báo chí | E27: 1 bài | F27: VnE hoặc Tuổi Trẻ
B28: CHƯƠNG TRÌNH KHUYẾN MÃI (5.10-20.10) (Đa dạng hơn các hình thức, tạo combo & giá cạnh tranh với mục tiêu Hút Traffic khách hàng mới. Cân đối các bài viết nhóm sản phẩm chim mồi & sản phẩm cao cấp)
B29: LOẠI CHƯƠNG TRÌNH | C29: NO | D29: TÊN CHƯƠNG TRÌNH | E29: THỜI GIAN | F29: CHI TIẾT/ĐIỀU KIỆN
B30: CT thường niên | C30: 1 | D30: SIÊU SALE GIẢM ĐẾN 50% Giảm đến 20% các sản phẩm tròng | E30: Xuyên suốt
C31: 2 | D31: Thu cũ đổi mới - Tiết kiệm 900K | E31: Xuyên suốt
C32: 3 | D32: Mua kính mát tặng tròng màu Chemi 830K | E32: Xuyên suốt | G32: Bổ sung Media mới
C33: 4 | D33: VN PAY | E33: Xuyên suốt | F33: Giảm 250k cho ZEISS Blue Protect 1.56 Giảm 300k cho Essilor Transition Classic 1.56 màu khói | G33: Bổ sung Media mới
B34: CT Mới | C34: 5 | D34: Hallo Bác tài: Tặng bộ kính Cận râm tháo lắp khi cắt tròng | E34: 5.10 - 20.10 | F34: Giảm 30% khi mua tròng kính (danh sách tròng kính áp dụng kèm theo)
C35: 6 | D35: Tậu kính Hiệu - Deal hời gấp bội | E35: 5.10 - 20.10 | F35: Giảm 20% trên giá niêm yết cho các mẫu gọng Molsion/Bolon Tặng voucher mua tròng nguyên giá 300K: Áp dụng cho tất cả các loại tròng.
B36: CT 20.10 | C36: 7 | D36: Vì bạn mãi là 1 bông hoa: Cho khách hàng nữ - Giảm 50% 20 mẫu gọng kính nữ best seller - Giảm 50% Kính mát Povino (tất cả) | E36: 18.10 - 20.10 | F36: Tặng hoa Sáp/hoa vải dưới 10K (từ ngày 18.10 cho đến khi hết quà) | G36: Phiếu quà tặng: Ý nghĩa của việc tặng kính | H36: Phiếu quà tặng: bắt trend làm TikTok chạy ads
B37: Chi nhánh | C37: 8 | D37: Quận 12: Tặng Free tròng Ecolite không cần phát sinh hóa đơn | E37: 5.10 - 20.10 | F37: Khi mua bất kỳ sản phẩm gọng nào. Nếu khách chỉ lấy tròng thì thu phí mài lắp.
C38: 9 | D38: Sinh nhật Gò vấp: 1. Tặng tròng Ecolite 282k 2. Mua tròng: + KODAK Blue 1.60 + CHEMI ASX U6 1.67 + VISION X 1.60 đổi màu asx + ZEISS Blue Protect 1.56 + ESSILOR Transitions Classic 1.56 màu khói Tặng gọng theo danh sách (gọng cty Đăng Anh Trí giá tối đa 639k) | E38: 12.10-16.10
B39: Back To School | C39: 11 | D39: Tựu trường bao vui - Khui ngay Marbook (tiếp diễn từ tháng 9 đến 10.10) | E39: hết 10.10

Sheet C.MKT Plan Openning Q9
B1: Địa chỉ: 252 Lê Văn Việt, P.Tăng Nhơn Phú | C1: PLAN KHAI TRƯƠNG CHI NHÁNH Q7
B2: KPI (2.11-31.12)
B3: DOANG THU | C3: BUDGET
A4: 2 THÁNG | B4: ='A.OKR&KPI 10-12.2024'!F22 | C4: ='A.OKR&KPI 10-12.2024'!F23
A5: DAY | B5: =B4/60 | C5: THÁNG KHAI TRƯƠNG | D5: =C4*85%
C6: THÁNG 12 | D6: =C4-D5
B7: ACTION PLAN: Action Plan Openning Q.9 25.10-30.11

Sheet D.Master Plan Sinh nhật 25.10-15.12
C2: KPI (25.10-15.12) | F2: KEY ACTIVITIES: | I2: IMC PLAN
C3: DOANH THU | D3: BUDGET | I3: GIÁ TRỊ & TRẢI NGHIỆM
B4: 25.10-15.12 | C4: =(('A.OKR&KPI 10-12.2024'!C5/31)*7)+((7000000000+(7000000000/31)*15)) | D4: =C4*6% | I4: Phase 1: 21.10-30.10 | K4: Phase 2: 1.11-30.11 | M4: Phase 3: 1.12-15.12
B5: DAY | C5: =C4/(30+15+7) | D5: =D4/C4 | F5: MARKETING OKR | I5: KPI | J5: ACTION | K5: KPI | L5: ACTION | M5: KPI | N5: ACTION
C6: BUDGET ALOCATION | F6: Nội dung Tái định vị | G6: Triển khai Tái định vị Phase 1: "Slogan & Câu chuyện thương hiệu"" | I6: truyền thông câu chuyện Thương hiệu + Clip giới thiệu Thương hiệu | K6: Công bố Website mới, Công bố & truyền thông Slogan "GIÁ TRỊ & TRẢI NGHIỆM" | M6: Tiếp tục truyền thông Slogan & phát triển các tagline. Triển khai 5S Tâm Đức.
B7: =D7/63 | C7: PAID MEDIA | D7: =D4*60% | F7: Khách hàng | G7: Tăng trưởng mạnh mẽ nhóm khách hàng mới & tỷ lệ quay lại khách hàng cũ | I7: Khách cũ 56.84% | K7: Khách cũ 60.76% | M7: Khách cũ 60.76%
B8: =D8/63 | C8: Facebook Ads | D8: =D7*80% | I8: Khách mới Growth 9% | K8: Khách mới Growth 13.5% | M8: Khách mới Growth 13.5%
B9: =D9/63 | C9: SEM | D9: =D7*5% | F9: Tăng trưởng các chỉ số Owned Media | G9: Tăng trưởng qua lượng Reach trên Social Media. | I9: 1.8 | J9: Thay đổi cách viết storytelling. Các nhóm bài viết giới thiệu về thương hiệu dựa trên câu chuyện thương hiệu: Tầm nhìn, giá trị cốt lõi, dịch vụ,... Cấu trúc nội dung Website mới với cách viết tập trung vào khách hàng & tăng chuyển đổi Sản xuất các Video với nội dung có giá trị & focus vào khách hàng. Các nội dung bắt trend bổ trợ. | K9: 2.7 | L9: Thay đổi cách viết storytelling. Các nhóm bài viết giới thiệu về thương hiệu dựa trên câu chuyện thương hiệu: Tầm nhìn, giá trị cốt lõi, dịch vụ,... Cấu trúc nội dung Website mới với cách viết tập trung vào khách hàng & tăng chuyển đổi Sản xuất các Video với nội dung có giá trị & focus vào khách hàng. Các nội dung bắt trend bổ trợ. | M9: 2.7 | N9: Thay đổi cách viết storytelling. Các nhóm bài viết giới thiệu về thương hiệu dựa trên câu chuyện thương hiệu: Tầm nhìn, giá trị cốt lõi, dịch vụ,... Cấu trúc nội dung Website mới với cách viết tập trung vào khách hàng & tăng chuyển đổi Sản xuất các Video với nội dung có giá trị & focus vào khách hàng. Các nội dung bắt trend bổ trợ.
B10: =D10/63 | C10: TikTok Ads | D10: =D7*6% | G10: Tăng trưởng qua lượng Engagement trên Social Media. | I10: 1.35 | K10: 1.8 | M10: 1.8
B11: =D11/63 | C11: Native Ads | D11: =D7*3% | G11: Tăng trưởng Traffic trên Website | I11: 0.18 | K11: 0.18 | M11: 0.18
B12: =D12/63 | C12: Youtube Ads | D12: =D8*3% | G12: Tăng trưởng Views Organic (TikTok/Facebook/Youtube) | I12: 200000 | J12: TikTok-Định hướng | K12: 1800000 | L12: TikTok-Định hướng | M12: 450000 | N12: TikTok-Định hướng
B13: =D13/63 | C13: GDN Ads | D13: =D7*3% | G13: Phát triển Kênh mới | I13: Linkedin | J13: Tập trung vào các tuyến nội dung về thương hiệu. | K13: Linkedin, Youtube | M13: Linkedin, Youtube
C14: BRAND & COMMUNICATION | D14: =D4-D7 | F14: Tạo thảo luận về Thương hiệu trên Social Media | G14: Thông qua UGC content bằng hình thức # | I14: #40 | K14: #225 | M14: #180
C15: Cuộc thi Đại sứ Thương hiệu/Đại diện hình ảnh | D15: 80000000 | F15: Tăng trưởng nhận diện Thương hiệu | G15: Qua Branded Merchandise | I15: #Sổ #giá đỡ điện thoại | K15: #Túi Tote #Nón bảo hiểm #Sổ #Giây đeo kính | M15: #Túi Tote #Nón bảo hiểm #Sổ #Giây đeo kính
C16: Viral Dance Cover | D16: 60000000 | G16: Media Booking - OOH | I16: Báo giá & check điểm triển khai
C17: PR-Báo | D17: 15000000 | G17: Đại sứ Thương hiệu/Đại diện hình ảnh | I17: SOW & Báo giá | J17: Influencer cho 02 nhóm khách hàng: - Nhóm 16-28: ? - Nhóm >28: Ông chú Polo | K17: 5.11 Công bố Đại sứ thương hiệu/Đại diện hình ảnh | L17: Hoạt động Mega Live, tung Album ảnh với sản phẩm, Short Video trên các nền tảng | N17: Hoạt động Mega Live, tung Album ảnh với sản phẩm, Short Video trên các nền tảng
C18: Unitour | D18: 30000000 | G18: Activations
C19: Quà tặng CT | D19: 70000000 | G19: Dance Cover | I19: Dance Viral Clip Tìm kiếm nhóm nhảy biên đạo & thực hiện quay bài. Plan chi tiết tại: Dance Viral Clip | J19: 21.10 Tung Dance Viral Clip 15.10 Thông báo cuộc thi Dance Cover (các nhóm nhảy THPT & Đại học Cao đẳng khu vực phía nam) | K19: 50 bài cover tham gia | L19: Đăng các clip tham gia trên TikTok & Short Video trên YouTuBe *Trường hợp hoạt động có độ phủ & Viral tốt sẽ tổ chức 1 buổi Offlne Trao giải & Dance Battle (16.11, target 2 ngàn sinh viên tham gia)
C20: Co-Branding | D20: 30000000 | F20: PR & COM | G20: Co-Branding & Partnership | I20: CGV, Dat Bike,
C21: Mega Live | D21: 20000000 | G21: Sponsor - Uni Tour | I21: Hoạt động Activations tại trường & phát voucher tăng chuyển đổi cho các chi nhánh. Ưu tiên cho chi nhánh Quận 9 & Thủ Đức.
D22: =SUM(D15:D21) | G22: Báo chí | K22: VnE, Tuổi Trẻ - Bài Phỏng vấn về Thương hiệu, Thị trường & CSR
G23: Seeding
F24: Promotion | G24: Đa dạng hơn các hình thức, tạo combo & giá cạnh tranh với mục tiêu Hút Traffic khách hàng mới. Gia tăng ưu đãi để tạo sự cạnh tranh với đối thủ
F25: Loyalty & Affiliate Program | G25: Chương trình Loyalty mới | I25: Chốt chính sách cho các hạng thẻ: Silver, Gold, Platinum CT cũ: https://matkinhtamduc.com/tich-diem-doi-qua/?utm_source=website&utm_medium=noti&utm_campaign=membership&utm_content=hoa CT Mới: Loyalty & Affiliate Program | K25: - Silver: 2.000 - Gold: 1.000 - Platinum - Khắc tên custom: 500 | M25: - Silver: 4.000 - Gold: 2.000 - Platinum - Khắc tên custom: 1.000
G26: Affiliate | I26: 1. Kết nối cộng đồng Doanh nghiệp JCI, BNI, Coach, Trainer, C-Level 2. Buiid chính sách Hoa hồng 3. Các hạng mức thẻ & mức chiết khấu mua | K26: 200 thẻ | M26: 400 thẻ
F27: PAID MEDIA | G27: Triển khai Brandformance & Các channel ads mới | I27: Kết hợp đồng thời 02 hình thức Paid Ads Brand Awareness & Conversion. | K27: 1. Kết hợp đồng thời 03 hình thức Paid Ads Brand Awareness & Conversion. 2. Channel mới: TikTok, Linkedin 3. Hình thức mới Natived Ads | M27: 1. Kết hợp đồng thời 03 hình thức Paid Ads Brand Awareness & Conversion. 2. Channel mới: TikTok, Linkedin 4. Hình thức mới Natived Ads

Sheet CTKM 8 Năm
E2: TÊN CHƯƠNG TRÌNH | F2: THỜI GIAN | G2: MÔ TẢ
B3: Sinh nhật 8 năm 21.10-15.12 | C3: CT Thường niên | D3: 1 | E3: SIÊU SALE GIẢM ĐẾN 50% Giảm đến 20% các sản phẩm tròng | F3: 21.10-15.12
D4: 2 | E4: Thu cũ đổi mới - Tiết kiệm 900K | F4: 21.10-15.12
C5: CT Sinh nhật toàn hệ thống | D5: 3 | E5: Chương trình bốc thăm trúng thưởng: 8.888 quà tặng - Mua Mắt kính - Tậu xe - Rinh vàng | F5: 1.11-15.12 | G5: Với hóa đơn bất kỳ có cơ hội tham gia Bốc thăm trúng - 1 giải đặc biệt: 01 xe máy điện Dat Bike? - 02 giải nhất: 01 cặp nhẫn vàng 24K - 10 giải 3: 5 cặp Tròng kính? 5 gọng kính - Hàng ngàn Giải khuyến khích: Sổ tay, giá đỡ điện thoại, giây đeo, voucher 100k, tròng kính Ecolite, nón bảo hiểm
D6: 4 | E6: Giảm thêm 8% khi mua Combo kính có giá trị hóa đơn từu 1tr8 | F6: 5.11-5.12
C7: Event Day | D7: 5 | E7: Sinh nhật 8 năm - Deal Đỉnh Nóc, Quà Kịch Trần - Bốc thăm trúng quà/Hóa đơn bất kỳ không giới hạn số lượng - Tặng Gọng kính best seller khi cắt tròng bất kỳ không giới hạn số lượng - Tặng tròng Ecolite không điều kiện, không giới hạn số lượng - Kính mát mua 1 tặng 1 | F7: 5.11
D8: 6 | E8: Mega Live Sinh Nhật (Ông chú Polo +...) - Deal: 999 gọng kính chính hãng giảm 88% | F8: 5.11 (19h-21h)
C9: CT Đối tác Thanh toán | D9: 7 | E9: VNPay | G9: Giảm 300k cho ZEISS Blue Protect 1.56 Giảm 350k cho Essilor Transition Classic 1.56 màu khói
D10: 8 | E10: Gotit
D11: 9 | E11: UrBox
D12: 10 | E12: MoMo
C13: CT Holiday | D13: 11 | E13: Ngày tri ân - Phiếu quà tặng - Giảm 50% 10 mẫu gọng kính best seller - Giảm thêm 5% combo gọng + kính cho các thầy cô giáo (Combo gọng+tròng bất kỳ) | F13: 20.11
D14: 12 | E14: Black friday - Deal sập sàn, quà liền tay: - Tặng tròng Ecolite không điều kiện - Gọng giảm 99% khi cắt từ tròng Chemi U2 - Kính mát: Mua 1 tặng 1 | F14: 21.11-30.11
C15: Uni Tour | D15: 13 | E15: Tặng tròng Ecolite không điều kiện | F15: 21.10-15.12
D16: 14 | E16: Combo Sinh viên (dùng Online + Voucher phát offline tài trợ) | F16: 21.10-15.13

Sheet Dance Viral Clip
B2: TẠO VIRAL TRÊN NỀN TẢNG TIKTOK THÔNG QUA DANCER VIRAL CLIP
B3: Phase 1: 21.10-30.10 | C3: Phase 2: 1.11-10.11 | D3: Phase 3: 11.11-16.11
B4: Kính mới bật chất mới - Bật vũ điệu mới
B5: Brief: Ref 1 Dance Thuần túy + Sản phẩm mắt kính + Đạo cụ Logo: https://www.facebook.com/gapinc.vn/videos/503075825681166/?mibextid=O563ZM&rdid=RNRzzNsmAAnMg2Rl Ref 2: Có câu chuyện hài hước: https://www.facebook.com/td.vangbacdaquykimtin/videos/843751374512744
B6: Tung Dance Viral Clip | C6: Tổ chức cuộc thi Dance Cover | D6: Offline
B7: 1 clip teaser | C7: 50 nhóm nhảy/50 bài cover tham gia dự thi | D7: 10 nhóm nhảy tham gia đêm chung kết
B8: 03 clip cắt cut
B9: 1 Clip chính

Sheet PR&Com
B2: CO-BRANDING & PARTNERSHIP
B3: HÌNH THỨC HỢP TÁC
B4: Co-Branding & Partnership | C4: 1 | D4: Trao đổi voucher | E4: 1. Tặng tròng Ecolite kèm điều kiện 2. Voucher giảm trực tiếp 100k áp dụng đồng thời.
C5: 2 | D5: Trao đổi quyền lợi truyền thông | E5: Online: Social Post & Banner hiển thị website Offline: POSM cửa hàng
B6: SCHEME CHƯƠNG TRÌNH KHUYẾN MÃI & PARTNERSHIP
B7: ĐỐI TÁC | C7: NO | D7: TÊN CHƯƠNG TRÌNH | E7: MÔ TẢ
B8: CO-BRANDING
B9: BTaskee | C9: 1 | D9: Tặng free tròng kính Ecolite cho hóa đơn từ 500K | E9: Khi cắt tròng từ
C10: 2 | D10: Tặng free gọng kính cho CTV của BTaskee có ngày sinh 20.10
C11: 3 | D11: Combo kiểm soát cận thị Chemi
B12: Coffee & Tea | C12: 1 | D12: Đổi điểm thành viên nhận free Tròng kính | E12: Khách hàng có điểm tiêu dùng từ... nhận ngay tròng kính Ecolite từ Tâm Đức.
C13: 2 | D13: Đổi điểm thành viên nhận Free nước uống từ | E13: Khách hàng có điểm tiêu dùng từ... nhận Free nước uống từ...
C14: 3 | D14: Khách hàng nữ có ngày sinh 20.10 nhận free gọng kính từ Tâm Đức
C15: 4
B16: Dat Bike | C16: 1
C17: 2
C18: 1
B19: PARTNERSHIP
C20: 3
C21: 1
C22: 2
C23: 3
C24: 1

Sheet Loyalty & Affiliate Program
B2: LOYALTY PROGRAM
B3: ĐIỀU KIỆN NÂNG HẠNG THẺ & DUY TRÌ THẺ
C4: Silver | D4: Gold | E4: Platinum
B5: Số điểm để đạt hạng | C5: KH có điểm tích lũy lũy kế từ... đến... điểm tương đương mua sắm trên... | D5: KH có điểm tích lũy lũy kế từ [...] đến [...] điểm, tương đương mua sắm trên... | E5: KH có điểm tích lũy lũy kế từ [...] điểm, tương đương mua sắm trên [...]
B6: Điều kiện duy trì hạng thẻ | D6: Tổng chi tiêu trong năm tối thiểu từ [...] | E6: Tổng chi tiêu trong năm tối thiểu từ [...]
B7: QUYỀN LỢI HẠNG THẺ
B8: Tỷ lệ tích điểm | C8: 2% giá trị đơn hàng | D8: 3% giá trị đơn hàng | E8: 5% giá trị đơn hàng
B9: Voucher theo hạng thành viên | C9: 0.05 | D9: 0.08 | E9: 0.1
B10: Quà tặng sinh nhật | C10: Quà từ Tâm Đức, quà từ đối tác Co-Brand. Giá trị quà/Hạng thành viên | D10: Quà từ Tâm Đức, quà từ đối tác Co-Brand. Giá trị quà/Hạng thành viên | E10: Quà từ Tâm Đức, quà từ đối tác Co-Brand. Giá trị quà/Hạng thành viên
B11: Sự kiện đặc biệt có thu phí
B12: Voucher chúc mừng thăng hạng
B13: Quy đổi điểm: 1 điểm=1000VNĐ
B14: - Tích điểm, tiêu tiêu điểm linh hoạt: Tích điểm sau khi mua hàng thành công, sử dụng khi mua sắm tiết kiệm hơn. - Quà tặng riêng đặc biệt: Quà tặng sinh nhật, thăng hạng và những dịp đặc biệt. - Trải nghiệm mua sắm "WOW": Các chương trình ưu đãi dành riêng, sự kiện độc quyền và nhiều quyền lợi hấp dẫn.
B16: AFFILIATE PROGRAM

Sheet Owned Media
B16: Plan SEO tổng thể: Plan SEO Tổng Thể
B17: NO | C17: HẠNG MỤC | D17: MÔ TẢ CHI TIẾT | E17: OKR | F17: KPI

Sheet Paid Media

Sheet 5.5-5S Tâm Đức

Sheet E.Marketing Plan 17.12-31.12
B2: KPI (17.12-31.12)
B3: DOANH THU | C3: BUDGET | E3: CT Thường niên | F3: 1 | G3: SIÊU SALE GIẢM ĐẾN 50% Giảm đến 20% các sản phẩm tròng
F4: 2 | G4: Thu cũ đổi mới
E5: CT Holiday | G5: Noel
B6: BUDGET ALOCATION | F6: 1 | G6: Tết Dương lịch
B7: PAID MEDIA
B8: Facebook Ads
B9: SEM
B10: SEO
B11: Native Ads
B12: Youtube Ads
B13: GDN
B14: BRAND & COMMUNICATION

Sheet Metrics Owned Media
A2: Website
A5: FANPAGE | G5: INSTAGRAM
A6: FLATFORM | B6: THÁNG 6 | C6: KPI THÁNG 7 (Tăng 110%) | D6: RESULT | E6: TỶ LỆ ĐẠT | G6: T7
A7: Fanpage - Reach organic | B7: 17943 | C7: 19737.3 | D7: 17247 | E7: 0.87382773 | G7: Instagram Reach | H7: 43735 | I7: 48108.5 | J7: 85290 | K7: 1.7728676
A8: Fanpage Reels - Views organic | B8: 3745 | C8: 4119.5 | D8: 5062 | E8: 1.2287899 | G8: Instagram Engagement | H8: 102 | I8: 112.2 | J8: 82 | K8: 0.73083779
A9: Fanpage Engagement organic | B9: 2283 | C9: 2511.3 | D9: 658 | E9: 0.26201569
A10: FLATFORM | B10: THÁNG 7 | C10: KPI THÁNG 8 (Tăng 110%) | D10: RESULT | E10: TỶ LỆ ĐẠT | G10: T8
A11: Reach organic | B11: 17247 | C11: 22000 | D11: 19398 | E11: =D11/C11 | G11: Reach organic | H11: 85290 | I11: 100000 | J11: 49194 | K11: =J11/I11
A12: Views organic | B12: 5062 | C12: 10000 | D12: 5842 | E12: =D12/C12 | G12: Engagement organic | H12: 82 | I12: 500 | J12: 67 | K12: =J12/I12
A13: Engagement organic | B13: 658 | C13: 1000 | D13: 914 | E13: =D13/C13 | G13: Followers | H13: 14 | I13: 20 | J13: 15 | K13: =J13/I13
A14: Followers | B14: 49 | C14: 90 | D14: 231 | E14: =D14/C14
A15: FLATFORM | B15: THÁNG 8 | C15: KPI THÁNG 9 (Tăng 130%) | D15: RESULT (01-19.09) | E15: TỶ LỆ ĐẠT | G15: T9
A16: Reach organic | B16: 19398 | C16: =B16*130% | D16: 16860 | E16: =B16/C16 | G16: Reach | H16: 49194 | I16: =H16*130% | J16: 39.239 | K16: =H16/I16
A17: Views organic | B17: 5842 | C17: =B17*130% | D17: 6134 | E17: =B17/C17 | G17: Engagement | H17: 67 | I17: =H17*130% | J17: 306 | K17: =H17/I17
A18: Engagement organic | B18: 914 | C18: =B18*130% | D18: 687 | E18: =B18/C18 | G18: Followers | H18: 15 | I18: =H18*130% | J18: 14 | K18: =H18/I18
A19: Followers | B19: 231 | C19: =B19*130% | D19: 233 | E19: =B19/C19
A21: ZALO OA
A22: T7
A23: Số người dùng xem nội dung | B23: 290 | C23: 319 | D23: 359 | E23: 1.1253918
A24: Số người dùng gửi tin nhắn | B24: 191 | C24: 210.1 | D24: 260 | E24: 1.2375059
A25: Số người quan tâm mới | B25: 16 | C25: 17.6 | D25: 24 | E25: 1.3636364
A26: T8
A27: Số người dùng xem nội dung | B27: 198 | C27: 500 | D27: 211 | E27: =D27/C27
A28: Số người dùng gửi tin nhắn | B28: 260 | C28: 300 | D28: 263 | E28: =D28/C28
A29: Số người quan tâm mới | B29: 24 | C29: 50 | D29: 16 | E29: =D29/C29
A30: T9
A31: Số người dùng xem thông tin trang | B31: 211 | C31: =B31*130% | D31: 157 | E31: =B31/C31
A32: Số người dùng gửi tin nhắn | B32: 263 | C32: =B32*130% | D32: 174 | E32: =B32/C32
A33: Số người quan tâm mới | B33: 16 | C33: =B33*130% | D33: 10 | E33: =B33/C33
A35: Linkedin
